<?xml version="1.0"?>

<robot name="lata">
  
  <link name="world" />
  
  <joint name="fixed" type="floating">
    <parent link="world"/>
    <child link="lata_link"/>
    <origin xyz="0 0 0" rpy="0 0 0" />
  </joint>
  
  <link name="lata_link">
    <visual>
      <geometry>
        <cylinder radius="0.03" length="0.125" />
      </geometry>
      <origin rpy="0 0 0" xyz="0 0 0.0625" />
      <material name="red">
        <color rgba="1 0 0 1" />
      </material>
    </visual>
    <collision>
      <origin rpy="0 0 0" xyz="0 0 0.0625" />
      <geometry>
        <cylinder radius="0.03" length="0.125" />
      </geometry>
    </collision>
    <inertial>
      <origin rpy="0 0 0" xyz="0 0 0.0625" />
      <mass value="0.01" />
      <inertia ixx="0.001" ixy="0.0" ixz="0.0" iyy="0.001" iyz="0.0" izz="0.001"/>  
    </inertial>
  </link>
  
  <gazebo reference="lata_link">
    <material>Gazebo/Red</material>
    <mu1>0.9</mu1>
    <mu2>0.9</mu2>
    <selfCollide>true</selfCollide>
    <turnGravityOff>false</turnGravityOff>  
  </gazebo>
  
</robot>
